2025-05-24 17:54:10,227 - distributed.nanny - INFO -         Start Nanny at: 'tcp://10.6.1.164:44893'
2025-05-24 17:54:11,186 - distributed.worker - INFO -       Start worker at:     tcp://10.6.1.164:44949
2025-05-24 17:54:11,186 - distributed.worker - INFO -          Listening to:     tcp://10.6.1.164:44949
2025-05-24 17:54:11,187 - distributed.worker - INFO -           Worker name:             SLURMCluster-3
2025-05-24 17:54:11,187 - distributed.worker - INFO -          dashboard at:           10.6.1.164:45375
2025-05-24 17:54:11,187 - distributed.worker - INFO - Waiting to connect to: tcp://146.186.150.11:35323
2025-05-24 17:54:11,187 - distributed.worker - INFO - -------------------------------------------------
2025-05-24 17:54:11,187 - distributed.worker - INFO -               Threads:                          1
2025-05-24 17:54:11,187 - distributed.worker - INFO -                Memory:                 100.00 GiB
2025-05-24 17:54:11,187 - distributed.worker - INFO -       Local Directory: /tmp/dask-scratch-space/worker-4nbsf2kg
2025-05-24 17:54:11,187 - distributed.worker - INFO - -------------------------------------------------
2025-05-24 17:54:11,236 - distributed.worker - INFO - Starting Worker plugin shuffle
2025-05-24 17:54:11,237 - distributed.worker - INFO -         Registered to: tcp://146.186.150.11:35323
2025-05-24 17:54:11,237 - distributed.worker - INFO - -------------------------------------------------
2025-05-24 17:54:11,237 - distributed.core - INFO - Starting established connection to tcp://146.186.150.11:35323
2025-05-24 18:32:35,003 - distributed.worker - ERROR - Compute Failed
Key:       model_climatology-cad288f0-15a6-4505-b7a9-7b26f03a15c8
State:     executing
Task:  <Task 'model_climatology-cad288f0-15a6-4505-b7a9-7b26f03a15c8' model_climatology(...)>
Exception: 'AttributeError("\'DataArrayGroupBy\' object has no attribute \'compute\'")'
Traceback: '  File "/tmp/ipykernel_2988808/3643833314.py", line 29, in model_climatology\n'

2025-05-24 18:33:22,323 - distributed.worker - ERROR - Compute Failed
Key:       model_climatology-ed2609e7-dadf-4d77-9556-850edeafa2d9
State:     executing
Task:  <Task 'model_climatology-ed2609e7-dadf-4d77-9556-850edeafa2d9' model_climatology(...)>
Exception: 'AttributeError("\'DataArrayGroupBy\' object has no attribute \'values\'")'
Traceback: '  File "/tmp/ipykernel_2988808/2710521840.py", line 30, in model_climatology\n'

2025-05-24 18:33:50,939 - distributed.worker - ERROR - Compute Failed
Key:       model_climatology-f061080b-11f6-4703-9464-ab1e8d3db0cb
State:     executing
Task:  <Task 'model_climatology-f061080b-11f6-4703-9464-ab1e8d3db0cb' model_climatology(...)>
Exception: 'AttributeError("\'DataArrayGroupBy\' object has no attribute \'compute\'")'
Traceback: '  File "/tmp/ipykernel_2988808/2030164690.py", line 29, in model_climatology\n'

slurmstepd: error: *** JOB 38705094 ON p-sc-2394 CANCELLED AT 2025-05-24T18:54:19 DUE TO TIME LIMIT ***
