2025-05-24 17:54:10,952 - distributed.nanny - INFO -         Start Nanny at: 'tcp://10.6.1.150:38775'
2025-05-24 17:54:11,966 - distributed.worker - INFO -       Start worker at:     tcp://10.6.1.150:39513
2025-05-24 17:54:11,967 - distributed.worker - INFO -          Listening to:     tcp://10.6.1.150:39513
2025-05-24 17:54:11,967 - distributed.worker - INFO -           Worker name:             SLURMCluster-2
2025-05-24 17:54:11,967 - distributed.worker - INFO -          dashboard at:           10.6.1.150:34449
2025-05-24 17:54:11,967 - distributed.worker - INFO - Waiting to connect to: tcp://146.186.150.11:35323
2025-05-24 17:54:11,967 - distributed.worker - INFO - -------------------------------------------------
2025-05-24 17:54:11,967 - distributed.worker - INFO -               Threads:                          1
2025-05-24 17:54:11,967 - distributed.worker - INFO -                Memory:                 100.00 GiB
2025-05-24 17:54:11,967 - distributed.worker - INFO -       Local Directory: /tmp/dask-scratch-space/worker-hdcyuyjj
2025-05-24 17:54:11,967 - distributed.worker - INFO - -------------------------------------------------
2025-05-24 17:54:12,020 - distributed.worker - INFO - Starting Worker plugin shuffle
2025-05-24 17:54:12,020 - distributed.worker - INFO -         Registered to: tcp://146.186.150.11:35323
2025-05-24 17:54:12,021 - distributed.worker - INFO - -------------------------------------------------
2025-05-24 17:54:12,021 - distributed.core - INFO - Starting established connection to tcp://146.186.150.11:35323
2025-05-24 18:29:30,092 - distributed.worker - ERROR - Compute Failed
Key:       model_climatology-e2541107-363a-4cad-bd7f-99b4a7ac3dd2
State:     executing
Task:  <Task 'model_climatology-e2541107-363a-4cad-bd7f-99b4a7ac3dd2' model_climatology(...)>
Exception: 'TypeError("percentile() got an unexpected keyword argument dict_keys([\'axis\'])")'
Traceback: '  File "/tmp/ipykernel_2988808/1873454783.py", line 31, in model_climatology\n  File "/storage/work/cta5244/.conda/envs/fwi_env/lib/python3.10/site-packages/xarray/core/groupby.py", line 1697, in reduce\n    return self.map(reduce_array, shortcut=shortcut)\n  File "/storage/work/cta5244/.conda/envs/fwi_env/lib/python3.10/site-packages/xarray/core/groupby.py", line 1596, in map\n    return self._combine(applied, shortcut=shortcut)\n  File "/storage/work/cta5244/.conda/envs/fwi_env/lib/python3.10/site-packages/xarray/core/groupby.py", line 1615, in _combine\n    applied_example, applied = peek_at(applied)\n  File "/storage/work/cta5244/.conda/envs/fwi_env/lib/python3.10/site-packages/xarray/core/utils.py", line 250, in peek_at\n    peek = next(gen)\n  File "/storage/work/cta5244/.conda/envs/fwi_env/lib/python3.10/site-packages/xarray/core/groupby.py", line 1595, in <genexpr>\n    applied = (maybe_wrap_array(arr, func(arr, *args, **kwargs)) for arr in grouped)\n  File "/storage/work/cta5244/.conda/envs/fwi_env/lib/python3.10/site-packages/xarray/core/groupby.py", line 1686, in reduce_array\n    return ar.reduce(\n  File "/storage/work/cta5244/.conda/envs/fwi_env/lib/python3.10/site-packages/xarray/core/variable.py", line 1662, in reduce\n    result = super().reduce(\n  File "/storage/work/cta5244/.conda/envs/fwi_env/lib/python3.10/site-packages/xarray/namedarray/core.py", line 920, in reduce\n    data = func(self.data, axis=axis, **kwargs)\n  File "/storage/work/cta5244/.conda/envs/fwi_env/lib/python3.10/site-packages/dask/array/core.py", line 1787, in __array_function__\n    return da_func(*args, **kwargs)\n  File "/storage/work/cta5244/.conda/envs/fwi_env/lib/python3.10/site-packages/dask/array/percentile.py", line 136, in percentile\n    raise TypeError(\n'

2025-05-24 18:33:11,761 - distributed.worker - ERROR - Compute Failed
Key:       model_climatology-e1520ef2-8e04-4279-8549-116085b01ac8
State:     executing
Task:  <Task 'model_climatology-e1520ef2-8e04-4279-8549-116085b01ac8' model_climatology(...)>
Exception: 'AttributeError("\'DataArrayGroupBy\' object has no attribute \'values\'")'
Traceback: '  File "/tmp/ipykernel_2988808/4048197669.py", line 30, in model_climatology\n'

2025-05-24 18:39:09,500 - distributed.worker - ERROR - Compute Failed
Key:       model_climatology-eb623041-c37e-4248-837d-246e3a14ecae
State:     long-running
Task:  <Task 'model_climatology-eb623041-c37e-4248-837d-246e3a14ecae' model_climatology(...)>
Exception: 'AttributeError("\'DataArrayGroupBy\' object has no attribute \'values\'")'
Traceback: '  File "/tmp/ipykernel_2988808/1634497432.py", line 30, in model_climatology\n'

2025-05-24 18:48:27,395 - distributed.worker - ERROR - Compute Failed
Key:       model_climatology-e268d33c-193e-41a8-9f1e-9608783f54c3
State:     executing
Task:  <Task 'model_climatology-e268d33c-193e-41a8-9f1e-9608783f54c3' model_climatology(...)>
Exception: 'TypeError("percentile() got an unexpected keyword argument dict_keys([\'axis\'])")'
Traceback: '  File "/tmp/ipykernel_2988808/936877025.py", line 36, in model_climatology\n  File "/storage/work/cta5244/.conda/envs/fwi_env/lib/python3.10/site-packages/xarray/core/groupby.py", line 1697, in reduce\n    return self.map(reduce_array, shortcut=shortcut)\n  File "/storage/work/cta5244/.conda/envs/fwi_env/lib/python3.10/site-packages/xarray/core/groupby.py", line 1596, in map\n    return self._combine(applied, shortcut=shortcut)\n  File "/storage/work/cta5244/.conda/envs/fwi_env/lib/python3.10/site-packages/xarray/core/groupby.py", line 1615, in _combine\n    applied_example, applied = peek_at(applied)\n  File "/storage/work/cta5244/.conda/envs/fwi_env/lib/python3.10/site-packages/xarray/core/utils.py", line 250, in peek_at\n    peek = next(gen)\n  File "/storage/work/cta5244/.conda/envs/fwi_env/lib/python3.10/site-packages/xarray/core/groupby.py", line 1595, in <genexpr>\n    applied = (maybe_wrap_array(arr, func(arr, *args, **kwargs)) for arr in grouped)\n  File "/storage/work/cta5244/.conda/envs/fwi_env/lib/python3.10/site-packages/xarray/core/groupby.py", line 1686, in reduce_array\n    return ar.reduce(\n  File "/storage/work/cta5244/.conda/envs/fwi_env/lib/python3.10/site-packages/xarray/core/variable.py", line 1662, in reduce\n    result = super().reduce(\n  File "/storage/work/cta5244/.conda/envs/fwi_env/lib/python3.10/site-packages/xarray/namedarray/core.py", line 920, in reduce\n    data = func(self.data, axis=axis, **kwargs)\n  File "/storage/work/cta5244/.conda/envs/fwi_env/lib/python3.10/site-packages/dask/array/core.py", line 1787, in __array_function__\n    return da_func(*args, **kwargs)\n  File "/storage/work/cta5244/.conda/envs/fwi_env/lib/python3.10/site-packages/dask/array/percentile.py", line 136, in percentile\n    raise TypeError(\n'

slurmstepd: error: *** JOB 38705087 ON p-sc-2380 CANCELLED AT 2025-05-24T18:54:19 DUE TO TIME LIMIT ***
