2025-05-24 19:44:09,009 - distributed.nanny - INFO -         Start Nanny at: 'tcp://10.6.1.191:34909'
2025-05-24 19:44:11,251 - distributed.worker - INFO -       Start worker at:     tcp://10.6.1.191:42575
2025-05-24 19:44:11,252 - distributed.worker - INFO -          Listening to:     tcp://10.6.1.191:42575
2025-05-24 19:44:11,252 - distributed.worker - INFO -           Worker name:             SLURMCluster-3
2025-05-24 19:44:11,252 - distributed.worker - INFO -          dashboard at:           10.6.1.191:44259
2025-05-24 19:44:11,252 - distributed.worker - INFO - Waiting to connect to: tcp://146.186.150.11:40059
2025-05-24 19:44:11,252 - distributed.worker - INFO - -------------------------------------------------
2025-05-24 19:44:11,252 - distributed.worker - INFO -               Threads:                          1
2025-05-24 19:44:11,252 - distributed.worker - INFO -                Memory:                 100.00 GiB
2025-05-24 19:44:11,252 - distributed.worker - INFO -       Local Directory: /tmp/dask-scratch-space/worker-t97yclw0
2025-05-24 19:44:11,252 - distributed.worker - INFO - -------------------------------------------------
2025-05-24 19:44:11,292 - distributed.worker - INFO - Starting Worker plugin shuffle
2025-05-24 19:44:11,293 - distributed.worker - INFO -         Registered to: tcp://146.186.150.11:40059
2025-05-24 19:44:11,293 - distributed.worker - INFO - -------------------------------------------------
2025-05-24 19:44:11,293 - distributed.core - INFO - Starting established connection to tcp://146.186.150.11:40059
2025-05-24 19:54:57,252 - distributed.worker - ERROR - Compute Failed
Key:       model_climatology-c371d9bc-00a9-4f6f-abd6-b5f85defeeb9
State:     long-running
Task:  <Task 'model_climatology-c371d9bc-00a9-4f6f-abd6-b5f85defeeb9' model_climatology(...)>
Exception: 'AttributeError("\'DataArray\' object has no attribute \'windspeed\'")'
Traceback: '  File "/tmp/ipykernel_2988808/2824502972.py", line 31, in model_climatology\n  File "/storage/work/cta5244/.conda/envs/fwi_env/lib/python3.10/site-packages/xarray/core/common.py", line 306, in __getattr__\n    raise AttributeError(\n'

